Traceback (most recent call last):
  File "c:\users\uenergia\appdata\local\programs\python\python36\lib\site-packages\nbclient\client.py", line 626, in _async_poll_for_reply
    msg = await ensure_async(self.kc.shell_channel.get_msg(timeout=new_timeout))
  File "c:\users\uenergia\appdata\local\programs\python\python36\lib\site-packages\nbclient\util.py", line 96, in ensure_async
    result = await obj
  File "C:\Users\uenergia\AppData\Roaming\Python\Python36\site-packages\jupyter_client\channels.py", line 230, in get_msg
    raise Empty
queue.Empty

During handling of the above exception, another exception occurred:

Traceback (most recent call last):
  File "c:\users\uenergia\appdata\local\programs\python\python36\lib\site-packages\jupyter_cache\executors\utils.py", line 56, in single_nb_execution
    record_timing=False,
  File "c:\users\uenergia\appdata\local\programs\python\python36\lib\site-packages\nbclient\client.py", line 1093, in execute
    return NotebookClient(nb=nb, resources=resources, km=km, **kwargs).execute()
  File "c:\users\uenergia\appdata\local\programs\python\python36\lib\site-packages\nbclient\util.py", line 84, in wrapped
    return just_run(coro(*args, **kwargs))
  File "c:\users\uenergia\appdata\local\programs\python\python36\lib\site-packages\nbclient\util.py", line 62, in just_run
    return loop.run_until_complete(coro)
  File "c:\users\uenergia\appdata\local\programs\python\python36\lib\asyncio\base_events.py", line 484, in run_until_complete
    return future.result()
  File "c:\users\uenergia\appdata\local\programs\python\python36\lib\site-packages\nbclient\client.py", line 560, in async_execute
    cell, index, execution_count=self.code_cells_executed + 1
  File "c:\users\uenergia\appdata\local\programs\python\python36\lib\site-packages\nbclient\client.py", line 838, in async_execute_cell
    exec_reply = await self.task_poll_for_reply
  File "c:\users\uenergia\appdata\local\programs\python\python36\lib\site-packages\nbclient\client.py", line 650, in _async_poll_for_reply
    await self._async_handle_timeout(timeout, cell)
  File "c:\users\uenergia\appdata\local\programs\python\python36\lib\site-packages\nbclient\client.py", line 698, in _async_handle_timeout
    "Cell execution timed out", timeout, cell
nbclient.exceptions.CellTimeoutError: A cell timed out while it was being executed, after 30 seconds.
The message was: Cell execution timed out.
Here is a preview of the cell contents:
-------------------
# Crear el modelo Elman RNN
model_elman = Sequential()
model_elman.add(SimpleRNN(50, input_shape=(12, 1), activation='tanh', return_sequences=False))
model_elman.add(Dense(1))
model_elman.compile(optimizer='adam', loss='mean_squared_error')

# Entrenar el modelo
history = model_elman.fit(X_train, y_train, epochs=100, batch_size=1, verbose=1)
-------------------

