Traceback (most recent call last):
  File "c:\users\uenergia\appdata\local\programs\python\python36\lib\site-packages\jupyter_cache\executors\utils.py", line 56, in single_nb_execution
    record_timing=False,
  File "c:\users\uenergia\appdata\local\programs\python\python36\lib\site-packages\nbclient\client.py", line 1093, in execute
    return NotebookClient(nb=nb, resources=resources, km=km, **kwargs).execute()
  File "c:\users\uenergia\appdata\local\programs\python\python36\lib\site-packages\nbclient\util.py", line 84, in wrapped
    return just_run(coro(*args, **kwargs))
  File "c:\users\uenergia\appdata\local\programs\python\python36\lib\site-packages\nbclient\util.py", line 62, in just_run
    return loop.run_until_complete(coro)
  File "c:\users\uenergia\appdata\local\programs\python\python36\lib\asyncio\base_events.py", line 484, in run_until_complete
    return future.result()
  File "c:\users\uenergia\appdata\local\programs\python\python36\lib\site-packages\nbclient\client.py", line 560, in async_execute
    cell, index, execution_count=self.code_cells_executed + 1
  File "c:\users\uenergia\appdata\local\programs\python\python36\lib\site-packages\nbclient\client.py", line 854, in async_execute_cell
    self._check_raise_for_error(cell, exec_reply)
  File "c:\users\uenergia\appdata\local\programs\python\python36\lib\site-packages\nbclient\client.py", line 756, in _check_raise_for_error
    raise CellExecutionError.from_cell_and_msg(cell, exec_reply_content)
nbclient.exceptions.CellExecutionError: An error occurred while executing the following cell:
------------------
# creando grafico
plt.figure(figsize=(10,8))

# creando gr√°fico de linea
sns.lineplot(data=df_vm,x='fechaoperacion',y='valor')

# monstrando gr√°fico
plt.show()
------------------

[1;31m---------------------------------------------------------------------------[0m
[1;31mNameError[0m                                 Traceback (most recent call last)
[1;32m<ipython-input-9-32fa9e921b20>[0m in [0;36m<module>[1;34m[0m
[0;32m      3[0m [1;33m[0m[0m
[0;32m      4[0m [1;31m# creando gr√°fico de linea[0m[1;33m[0m[1;33m[0m[1;33m[0m[0m
[1;32m----> 5[1;33m [0msns[0m[1;33m.[0m[0mlineplot[0m[1;33m([0m[0mdata[0m[1;33m=[0m[0mdf_vm[0m[1;33m,[0m[0mx[0m[1;33m=[0m[1;34m'fechaoperacion'[0m[1;33m,[0m[0my[0m[1;33m=[0m[1;34m'valor'[0m[1;33m)[0m[1;33m[0m[1;33m[0m[0m
[0m[0;32m      6[0m [1;33m[0m[0m
[0;32m      7[0m [1;31m# monstrando gr√°fico[0m[1;33m[0m[1;33m[0m[1;33m[0m[0m

[1;31mNameError[0m: name 'df_vm' is not defined
NameError: name 'df_vm' is not defined

